<?xml version="1.0"?>
<robot xmlns:xacro="http://www.ros.org/wiki/xacro" name="navvis">
‌ <Link name="base">
  <visual>
    <origin xyz= "0.0 0.0 0.96" rpy="0.0 0.0 0.0" />
    <geometry>
        <box size="0.45 0.78 1.92" />
    </geometry>
  </visual>
  <collision>
    <origin xyz= "0.0 0.0 0.96" rpy="0.0 0.0 0.0" />
    <geometry>
      <box size="0.45 0.78 1.92"/>
    </geometry>
  </collision>
  </Link>    
 <Link name="laser_vert_bottom">
  <visual>
    <origin xyz= "0.3158 -0.0021 0.51" rpy="3.1355 -1.3045 0.0025" />
    <geometry>
     <box size="0.62 0.62 0.87" />
    </geometry>
  </visual>
  <collsion>
    <origin xyz= "0.3158 -0.0021 0.51" rpy="3.1355 -1.3045 0.0025" />
    <geometry>
     <box size="0.62 0.62 0.87" />
    </geometry>
  </collsion>
   </Link>

 <joint name="base_laser_vert_bottom_joint" type="fixed">
  <parent link="base" />
  <child link="laser_vert_bottom_joint" />
  <origin xyz= "0.3158 -0.0021 0.51" rpy="3.1355 -1.3045 0.0025" />
 </joint>

 <Link name="laser_vert_top_right">
  <visual>
    <origin xyz= "0.2978 -.1450 1.8541" rpy="-1.176 0.6313 -1.9377" />
    <geometry>
        <box size="0.62 0.62 .87" />
    </geometry>
  </visual>
  <collision>
    <origin xyz= "0.2978 -.1450 1.8541" rpy="-1.176 0.6313 -1.9377" />
    <geometry>
        <box size="0.62 0.62 .87" />
    </geometry>
  </collision>
  </Link>   
  <joint name="base_laser_vert_top_right_joint" type="fixed">
    <parent link="base" />
    <child link="laser_vert_top_right_joint" />
    <origin xyz= "0.2978 -.1450 1.8541" rpy="-1.176 0.6313 -1.9377" />
   </joint>
   <Link name="laser_vert_top_left">
    <visual>
      <origin xyz= "0.2997 0.1531 1.8443" rpy="-1.176 0.6198 1.956" />
      <geometry>
          <box size="0.62 0.62 .87" />
      </geometry>
    </visual>
    <collision>
      <origin xyz= "0.2997 0.1531 1.8443" rpy="-1.176 0.6198 1.956" />
      <geometry>
          <box size="0.62 0.62 .87" />
      </geometry>
    </collision>
    </Link>   
    <joint name="base_laser_vert_top_left_joint" type="fixed">
      <parent link="base" />
      <child link="laser_vert_top_left_joint" />
      <origin xyz= "0.2997 0.1531 1.8443" rpy="-1.176 0.6198 1.956" />
     </joint>
     <Link name="laser_horiz">
      <visual>
        <origin xyz= "0.2325 0.0001 1.9201" rpy="-0.0012 0.1146 -0.0015" />
        <geometry>
            <cylinder radius="0.52" length="0.72"/> 
        </geometry>
      </visual>
      <collision>
        <origin xyz= "0.2325 0.0001 1.9201" rpy="-0.0012 0.1146 -0.0015"  />
        <geometry>
          <cylinder radius="0.52" length="0.72"/> 
        </geometry>
      </collision>
      </Link>   
      <joint name="base_laser_horiz_joint" type="fixed">
        <parent link="base" />
        <child link="laser_horiz_joint" />
        <origin xyz= "0.2325 0.0001 1.9201" rpy="-0.0012 0.1146 -0.0015"  />
       </joint>
       <!-- XACRO Macro definition block to add around the wheel link and joing ! -->
    <xacro:macro name="wheel_side" params="side reflect">
         <Link name="wheel_${side}">
        <visual>
          <origin xyz= "-.1 ${reflect *0.4} 0" rpy="-1.516 0.0 0.0" />
          <geometry>
              <cylinder radius="0.2" length="0.05"/> 
          </geometry>
        </visual>
        <collision>
          <origin xyz= "-.1 ${reflect *0.4} 0" rpy="-1.516 0.0 0.0" />
          <geometry>
            <cylinder radius="0.2" length="0.05"/> 
          </geometry>
        </collision>
        </Link>   
        <joint name="base_wheel_${side}_joint" type="continuous">
          <parent link="base" />
          <child link="wheel_${side}_joint" />
          <origin xyz= "-.1 ${reflect *0.4} 0" rpy="-1.516 0.0 0.0" />
           </joint>
          </xacro:macro>   
          <!-- Call the XACRO Macro. It should be the left wheel !-->
     <xacro:wheel_side  side="left" reflect="1"  />
     <xacro:wheel_side side="right" reflect="-1"  />
        

          <xacro:macro name="wheel_center" />
            <Link name="wheel_center">
           <visual>
             <origin xyz= "-.1 0 -0.025" rpy="-1.516 0.0 0.0" />
             <geometry>
                 <cylinder radius="0.15" length="0.05"/> 
             </geometry>
           </visual>
           <collision>
             <origin xyz= "0.1 0 -0.025" rpy="-1.516 0.0 0.0" />
             <geometry>
               <cylinder radius="0.15" length="0.05"/> 
             </geometry>
           </collision>
           </Link>   
           <joint name="base_wheel_center_joint" type="continuous">
             <parent link="base" />
             <child link="wheel_center_joint" />
             <origin xyz= "0.1 0 -0.025" rpy="-1.516 0.0 0.0" />
              </joint>
           <xacro:wheel_center />          
           
</robot>
